Workbook

Sheet data
A1: v1 | B1: v2 | C1: v3 | D1: v4 | E1: v5 | F1: v6 | G1: v7 | H1: v8 | I1: v9 | J1: v10 | K1: v11 | L1: v12 | M1: v13 | N1: v14 | O1: v15 | P1: v16 | Q1: v17 | R1: v18 | S1: v19 | T1: v20 | U1: v21 | V1: v22 | W1: v23 | X1: v24 | Y1: v25 | Z1: v26 | AA1: v27 | AB1: v28 | AC1: v29 | AD1: v30 | AE1: v31 | AF1: v32 | AG1: v33 | AH1: v34 | AI1: v35 | AJ1: v36 | AK1: v37 | AL1: v38 | AM1: v39 | AN1: v40 | AO1: v41 | AP1: v42 | AQ1: v43 | AR1: v44 | AS1: v45 | AT1: v46 | AU1: v47 | AV1: v48 | AW1: v49 | AX1: v50 | AY1: v51 | AZ1: v52 | BA1: v53 | BB1: v54 | BC1: v55 | BD1: v56 | BE1: v57 | BF1: v58 | BG1: v59 | BH1: v60 | BI1: v61 | BJ1: v62 | BK1: v63 | BL1: v64 | BM1: v65 | BN1: v66 | BO1: v67 | BP1: v68 | BQ1: v69 | BR1: v70 | BS1: v71 | BT1: v72 | BU1: v73 | BV1: v74 | BW1: v75 | BX1: v76 | BY1: v77 | BZ1: v78 | CA1: v79 | CB1: v80 | CC1: v81 | CD1: v82 | CE1: v83 | CF1: v84 | CG1: v85 | CH1: v86 | CI1: v87 | CJ1: v88 | CK1: v89 | CL1: v90 | CM1: v91 | CN1: v92 | CO1: v93 | CP1: v94 | CQ1: v95 | CR1: v96 | CS1: v97 | CT1: v98 | CU1: v99 | CV1: v100 | CW1: v101 | CX1: v102 | CY1: v103 | CZ1: v104 | DA1: v105 | DB1: v106 | DC1: v107 | DD1: v108 | DE1: v109 | DF1: v110 | DG1: v111 | DH1: v112 | DI1: v113 | DJ1: v114 | DK1: v115 | DL1: v116 | DM1: v117 | DN1: v118 | DO1: v119 | DP1: v120 | DQ1: v121 | DR1: v122 | DS1: v123 | DT1: v124 | DU1: v125 | DV1: v126 | DW1: v127 | DX1: v128 | DY1: v129 | DZ1: v130 | EA1: v131 | EB1: v132 | EC1: v133 | ED1: v134 | EE1: v135 | EF1: v136 | EG1: v137 | EH1: v138 | EI1: v139 | EJ1: v140 | EK1: v141 | EL1: v142 | EM1: v143 | EN1: v144 | EO1: v145 | EP1: v146 | EQ1: v147 | ER1: v148 | ES1: v149 | ET1: v150 | EU1: v151 | EV1: v152 | EW1: v153 | EX1: v154 | EY1: v155 | EZ1: v156 | FA1: v157 | FB1: v158 | FC1: v159 | FD1: v160 | FE1: v161 | FF1: v162 | FG1: v163 | FH1: v164 | FI1: v165 | FJ1: v166 | FK1: v167 | FL1: v168 | FM1: v169 | FN1: v170 | FO1: v171 | FP1: v172 | FQ1: v173 | FR1: v174 | FS1: v175 | FT1: v176 | FU1: v177 | FV1: v178 | FW1: v179 | FX1: v180 | FY1: v181 | FZ1: v182 | GA1: v183 | GB1: v184 | GC1: v185 | GD1: v186 | GE1: v187 | GF1: v188 | GG1: v189 | GH1: v190 | GI1: v191 | GJ1: v192 | GK1: v193 | GL1: v194 | GM1: v195 | GN1: v196 | GO1: v197 | GP1: v198 | GQ1: v199 | GR1: v200 | GS1: v201 | GT1: v202 | GU1: v203 | GV1: v204 | GW1: v205 | GX1: v206 | GY1: v207 | GZ1: v208 | HA1: v209 | HB1: v210 | HC1: v211 | HD1: v212 | HE1: v213 | HF1: v214 | HG1: v215 | HH1: v216 | HI1: v217 | HJ1: v218 | HK1: v219 | HL1: v220 | HM1: v221 | HN1: v222 | HO1: v223 | HP1: v224 | HQ1: v225 | HR1: v226 | HS1: v227 | HT1: v228 | HU1: v229 | HV1: v230 | HW1: v231 | HX1: v232 | HY1: v233 | HZ1: v234 | IA1: v235 | IB1: v236 | IC1: v237 | ID1: v238 | IE1: v239 | IF1: v240 | IG1: v241 | IH1: v242 | II1: v243 | IJ1: v244 | IK1: v245 | IL1: v246 | IM1: v247 | IN1: v248 | IO1: v249 | IP1: v250
A2: 1154.4 | B2: 399.3 | C2: 533.3 | D2: 427.2 | E2: 980.6 | F2: 1901.7 | G2: 1434.1 | H2: 279.7 | I2: 1778.4 | J2: 2195.8 | K2: 993.4 | L2: 535.7 | M2: 2223.6 | N2: 546.6 | O2: 868.2 | P2: 705.3 | Q2: 1903.2 | R2: 2541.1 | S2: 2323.7 | T2: 2253.6 | U2: 189.9 | V2: -58.4 | W2: 439.7 | X2: 1088.2 | Y2: 731 | Z2: 1928.8 | AA2: 1827.9 | AB2: 1467.6 | AC2: 1832.9 | AD2: 427.2 | AE2: 2437.9 | AF2: 1028.8 | AG2: -6.7 | AH2: 532.3 | AI2: 155.6 | AJ2: 981.4 | AK2: 321.9 | AL2: 924.6 | AM2: 1688.4 | AN2: 630.2 | AO2: 2207.1 | AP2: 2160.9 | AQ2: 696.2 | AR2: 1261 | AS2: 2327.2 | AT2: 1069.4 | AU2: 773.8 | AV2: 261.4 | AW2: 2547 | AX2: 1248.5 | AY2: 1440.7 | AZ2: 2057.2 | BA2: 487.1 | BB2: 225.5 | BC2: 2520.3 | BD2: 900.2 | BE2: 833.5 | BF2: 2644.9 | BG2: 903.6 | BH2: 1743 | BI2: 276 | BJ2: 1160 | BK2: 1589.8 | BL2: 1721.3 | BM2: 1488.7 | BN2: 2252.5 | BO2: 347.6 | BP2: 1578.8 | BQ2: 1693.4 | BR2: 226.8 | BS2: 423.5 | BT2: 2474.4 | BU2: 340.6 | BV2: 1890.6 | BW2: 1529.1 | BX2: 2128.2 | BY2: -9.5 | BZ2: 976 | CA2: 418 | CB2: 1909.5 | CC2: 52.9 | CD2: 277.5 | CE2: 2315.3 | CF2: 1259.6 | CG2: 1113.1 | CH2: 2251.5 | CI2: 1702.1 | CJ2: 2156.9 | CK2: 180.7 | CL2: 2484 | CM2: 3088 | CN2: 1310 | CO2: 620 | CP2: 3148 | CQ2: 637 | CR2: 1113 | CS2: 870 | CT2: 2650 | CU2: 3610 | CV2: 3290 | CW2: 3201 | CX2: 104 | CY2: -269 | CZ2: 475 | DA2: 1446 | DB2: 910 | DC2: 2693 | DD2: 2547 | DE2: 2012 | DF2: 2556 | DG2: 459 | DH2: 3445 | DI2: 1347 | DJ2: -191 | DK2: 612 | DL2: 49 | DM2: 1279 | DN2: 301 | DO2: 1207 | DP2: 2330 | DQ2: 764 | DR2: 3124 | DS2: 3042 | DT2: 864 | DU2: 1710 | DV2: 3308 | DW2: 1415 | DX2: 976 | DY2: 209 | DZ2: 3631 | EA2: 1691 | EB2: 1980 | EC2: 2894 | ED2: 547 | EE2: 152 | EF2: 3591 | EG2: 1163 | EH2: 1060 | EI2: 3752 | EJ2: 1172 | EK2: 2429 | EL2: 229 | EM2: 1559 | EN2: 2201 | EO2: 2396 | EP2: 2054 | EQ2: 3180 | ER2: 336 | ES2: 2187 | ET2: 2353 | EU2: 160 | EV2: 450 | EW2: 3512 | EX2: 325 | EY2: 2631 | EZ2: 2113 | FA2: 549 | FB2: 301 | FC2: 341 | FD2: 520 | FE2: 1081 | FF2: 1262 | FG2: 613 | FH2: 751 | FI2: 1517 | FJ2: 1203 | FK2: 539 | FL2: 1032 | FM2: 1036 | FN2: 494 | FO2: 557 | FP2: 971 | FQ2: 1706 | FR2: 1874 | FS2: 1759 | FT2: 905 | FU2: -20 | FV2: 80 | FW2: 539 | FX2: 655 | FY2: 992 | FZ2: 1430 | GA2: 1246 | GB2: 1248 | GC2: 832 | GD2: 1074 | GE2: 1314 | GF2: 337 | GG2: 138 | GH2: 203 | GI2: 383 | GJ2: 449 | GK2: 426 | GL2: 973 | GM2: 855 | GN2: 1063 | GO2: 1675 | GP2: 1071 | GQ2: 711 | GR2: 1363 | GS2: 1286 | GT2: 665 | GU2: 342 | GV2: 1051 | GW2: 1446 | GX2: 1003 | GY2: 1327 | GZ2: 946 | HA2: 213 | HB2: 1026 | HC2: 1296 | HD2: 621 | HE2: 1319 | HF2: 1347 | HG2: 986 | HH2: 735 | HI2: 502 | HJ2: 1028 | HK2: 1252 | HL2: 1212 | HM2: 1424 | HN2: 968 | HO2: 698 | HP2: 1237 | HQ2: 696 | HR2: 188 | HS2: 1087 | HT2: 1054 | HU2: 820 | HV2: 1296 | HW2: 1391 | HX2: 775 | HY2: 314 | HZ2: 485 | IA2: 859 | IB2: 713 | IC2: 60 | ID2: 965 | IE2: 1358 | IF2: 877 | IG2: 1274 | IH2: 1509 | II2: 1471 | IJ2: 863 | IK2: 994 | IL2: 2157 | IM2: 1687 | IN2: 700 | IO2: 1435 | IP2: 1803
A3: 1153.7 | B3: 394.5 | C3: 550.5 | D3: 471 | E3: 1004.6 | F3: 1922 | G3: 1444.9 | H3: 274.1 | I3: 1776.8 | J3: 2175 | K3: 995.4 | L3: 558 | M3: 2220.3 | N3: 550.5 | O3: 870.3 | P3: 667.6 | Q3: 1897.2 | R3: 2469.5 | S3: 2319.4 | T3: 2303.9 | U3: 176.5 | V3: -65.8 | W3: 401.8 | X3: 1092.1 | Y3: 709.8 | Z3: 1909.2 | AA3: 1798.7 | AB3: 1459 | AC3: 1881.8 | AD3: 471 | AE3: 2458.5 | AF3: 1017.7 | AG3: -54.6 | AH3: 510.2 | AI3: 153.1 | AJ3: 987.8 | AK3: 341 | AL3: 862.2 | AM3: 1671.4 | AN3: 623 | AO3: 2204.5 | AP3: 2135.2 | AQ3: 704.8 | AR3: 1294.3 | AS3: 2320.5 | AT3: 1053 | AU3: 838.3 | AV3: 258.3 | AW3: 2523 | AX3: 1253.9 | AY3: 1404.5 | AZ3: 2055.5 | BA3: 519.7 | BB3: 210.1 | BC3: 2496.5 | BD3: 880.2 | BE3: 834 | BF3: 2633.8 | BG3: 905.4 | BH3: 1749 | BI3: 268.6 | BJ3: 1140.3 | BK3: 1617.6 | BL3: 1712.1 | BM3: 1473.4 | BN3: 2252.9 | BO3: 343.2 | BP3: 1512.9 | BQ3: 1717.4 | BR3: 241.3 | BS3: 416.9 | BT3: 2459 | BU3: 319.5 | BV3: 1937.8 | BW3: 1439 | BX3: 2131.5 | BY3: -58.5 | BZ3: 962.9 | CA3: 415.6 | CB3: 1899 | CC3: 61.1 | CD3: 278 | CE3: 2309.1 | CF3: 1306.8 | CG3: 1102.2 | CH3: 2209.8 | CI3: 1700.8 | CJ3: 2118.2 | CK3: 183.6 | CL3: 2460 | CM3: 3066 | CN3: 1305 | CO3: 650 | CP3: 3143 | CQ3: 639 | CR3: 1118 | CS3: 811 | CT3: 2646 | CU3: 3506 | CV3: 3297 | CW3: 3261 | CX3: 81 | CY3: -279 | CZ3: 415 | DA3: 1452 | DB3: 884 | DC3: 2660 | DD3: 2494 | DE3: 2000 | DF3: 2640 | DG3: 522 | DH3: 3487 | DI3: 1337 | DJ3: -263 | DK3: 576 | DL3: 50 | DM3: 1297 | DN3: 330 | DO3: 1107 | DP3: 2324 | DQ3: 744 | DR3: 3097 | DS3: 3009 | DT3: 866 | DU3: 1756 | DV3: 3285 | DW3: 1397 | DX3: 1064 | DY3: 206 | DZ3: 3596 | EA3: 1685 | EB3: 1923 | EC3: 2890 | ED3: 592 | EE3: 129 | EF3: 3544 | EG3: 1134 | EH3: 1066 | EI3: 3763 | EJ3: 1171 | EK3: 2441 | EL3: 221 | EM3: 1518 | EN3: 2224 | EO3: 2373 | EP3: 2031 | EQ3: 3198 | ER3: 331 | ES3: 2075 | ET3: 2390 | EU3: 179 | EV3: 437 | EW3: 3492 | EX3: 292 | EY3: 2709 | EZ3: 1977 | FA3: 547 | FB3: 306 | FC3: 331 | FD3: 512 | FE3: 1098 | FF3: 1275 | FG3: 615 | FH3: 748 | FI3: 1509 | FJ3: 1196 | FK3: 549 | FL3: 1039 | FM3: 1036 | FN3: 496 | FO3: 543 | FP3: 954 | FQ3: 1674 | FR3: 1843 | FS3: 1777 | FT3: 920 | FU3: -28 | FV3: 62 | FW3: 525 | FX3: 649 | FY3: 975 | FZ3: 1411 | GA3: 1231 | GB3: 1264 | GC3: 869 | GD3: 1100 | GE3: 1318 | GF3: 313 | GG3: 110 | GH3: 193 | GI3: 384 | GJ3: 459 | GK3: 409 | GL3: 941 | GM3: 846 | GN3: 1059 | GO3: 1664 | GP3: 1064 | GQ3: 727 | GR3: 1374 | GS3: 1277 | GT3: 684 | GU3: 366 | GV3: 1040 | GW3: 1439 | GX3: 991 | GY3: 1312 | GZ3: 958 | HA3: 220 | HB3: 1010 | HC3: 1278 | HD3: 613 | HE3: 1315 | HF3: 1343 | HG3: 990 | HH3: 735 | HI3: 491 | HJ3: 1031 | HK3: 1260 | HL3: 1202 | HM3: 1418 | HN3: 966 | HO3: 670 | HP3: 1220 | HQ3: 711 | HR3: 191 | HS3: 1078 | HT3: 1039 | HU3: 831 | HV3: 1279 | HW3: 1356 | HX3: 757 | HY3: 290 | HZ3: 479 | IA3: 854 | IB3: 712 | IC3: 63 | ID3: 963 | IE3: 1374 | IF3: 891 | IG3: 1253 | IH3: 1492 | II3: 1455 | IJ3: 849 | IK3: 985 | IL3: 2138 | IM3: 1676 | IN3: 710 | IO3: 1445 | IP3: 1802
A4: 1152.6 | B4: 399.7 | C4: 525.3 | D4: 437.5 | E4: 992.7 | F4: 1961.1 | G4: 1460.4 | H4: 277.3 | I4: 1771.7 | J4: 2174.2 | K4: 986.9 | L4: 561.2 | M4: 2218.1 | N4: 551.9 | O4: 841.7 | P4: 690.3 | Q4: 1901.6 | R4: 2494 | S4: 2320 | T4: 2292.3 | U4: 176.5 | V4: -56.2 | W4: 474.3 | X4: 1089.2 | Y4: 718.8 | Z4: 1889.6 | AA4: 1828.8 | AB4: 1488.1 | AC4: 1909 | AD4: 437.5 | AE4: 2437.5 | AF4: 993 | AG4: 5.2 | AH4: 512.7 | AI4: 148.6 | AJ4: 999.3 | AK4: 340.9 | AL4: 891.2 | AM4: 1672.2 | AN4: 632.3 | AO4: 2213.3 | AP4: 2080.3 | AQ4: 703.3 | AR4: 1326 | AS4: 2296.6 | AT4: 1063.4 | AU4: 800 | AV4: 257.3 | AW4: 2534.5 | AX4: 1236.1 | AY4: 1454.6 | AZ4: 2032.8 | BA4: 529.1 | BB4: 174.7 | BC4: 2515 | BD4: 885.1 | BE4: 830 | BF4: 2610.4 | BG4: 896.1 | BH4: 1754.6 | BI4: 242 | BJ4: 1169.7 | BK4: 1612.3 | BL4: 1715.1 | BM4: 1452.5 | BN4: 2265.4 | BO4: 330.5 | BP4: 1543 | BQ4: 1705.2 | BR4: 187.4 | BS4: 403.8 | BT4: 2488.9 | BU4: 300.6 | BV4: 1936.7 | BW4: 1486.1 | BX4: 2080.4 | BY4: 4.8 | BZ4: 952.5 | CA4: 415.5 | CB4: 1949.4 | CC4: 49.7 | CD4: 277.3 | CE4: 2281.3 | CF4: 1202.5 | CG4: 1125.3 | CH4: 2157.7 | CI4: 1700.2 | CJ4: 2127.7 | CK4: 180.2 | CL4: 2469 | CM4: 3061 | CN4: 1288 | CO4: 661 | CP4: 3133 | CQ4: 640 | CR4: 1076 | CS4: 852 | CT4: 2651 | CU4: 3534 | CV4: 3269 | CW4: 3231 | CX4: 83 | CY4: -264 | CZ4: 529 | DA4: 1447 | DB4: 890 | DC4: 2633 | DD4: 2557 | DE4: 2034 | DF4: 2659 | DG4: 467 | DH4: 3448 | DI4: 1301 | DJ4: -175 | DK4: 583 | DL4: 38 | DM4: 1311 | DN4: 324 | DO4: 1143 | DP4: 2320 | DQ4: 762 | DR4: 3116 | DS4: 2933 | DT4: 869 | DU4: 1797 | DV4: 3252 | DW4: 1406 | DX4: 1006 | DY4: 203 | DZ4: 3587 | EA4: 1655 | EB4: 1988 | EC4: 2849 | ED4: 605 | EE4: 78 | EF4: 3566 | EG4: 1141 | EH4: 1064 | EI4: 3717 | EJ4: 1152 | EK4: 2432 | EL4: 182 | EM4: 1558 | EN4: 2237 | EO4: 2393 | EP4: 1989 | EQ4: 3216 | ER4: 308 | ES4: 2121 | ET4: 2363 | EU4: 96 | EV4: 422 | EW4: 3536 | EX4: 268 | EY4: 2703 | EZ4: 2034 | FA4: 549 | FB4: 298 | FC4: 317 | FD4: 504 | FE4: 1109 | FF4: 1296 | FG4: 623 | FH4: 747 | FI4: 1506 | FJ4: 1192 | FK4: 547 | FL4: 1040 | FM4: 1036 | FN4: 485 | FO4: 541 | FP4: 965 | FQ4: 1686 | FR4: 1853 | FS4: 1773 | FT4: 915 | FU4: -24 | FV4: 95 | FW4: 553 | FX4: 651 | FY4: 971 | FZ4: 1415 | GA4: 1255 | GB4: 1287 | GC4: 866 | GD4: 1078 | GE4: 1300 | GF4: 327 | GG4: 135 | GH4: 192 | GI4: 387 | GJ4: 464 | GK4: 421 | GL4: 953 | GM4: 850 | GN4: 1066 | GO4: 1645 | GP4: 1041 | GQ4: 740 | GR4: 1377 | GS4: 1272 | GT4: 673 | GU4: 351 | GV4: 1045 | GW4: 1436 | GX4: 1004 | GY4: 1323 | GZ4: 953 | HA4: 209 | HB4: 1004 | HC4: 1288 | HD4: 614 | HE4: 1304 | HF4: 1330 | HG4: 988 | HH4: 726 | HI4: 492 | HJ4: 1041 | HK4: 1259 | HL4: 1195 | HM4: 1415 | HN4: 966 | HO4: 677 | HP4: 1227 | HQ4: 685 | HR4: 164 | HS4: 1085 | HT4: 1044 | HU4: 823 | HV4: 1297 | HW4: 1354 | HX4: 762 | HY4: 311 | HZ4: 475 | IA4: 874 | IB4: 727 | IC4: 59 | ID4: 951 | IE4: 1321 | IF4: 859 | IG4: 1241 | IH4: 1471 | II4: 1459 | IJ4: 851 | IK4: 987 | IL4: 2140 | IM4: 1667 | IN4: 707 | IO4: 1445 | IP4: 1798
A5: 1217.9 | B5: 394.5 | C5: 549.4 | D5: 465.6 | E5: 996.6 | F5: 1938.2 | G5: 1455.8 | H5: 279.9 | I5: 1774.3 | J5: 2166.8 | K5: 989.7 | L5: 556.6 | M5: 2222.6 | N5: 542.7 | O5: 845.9 | P5: 714.6 | Q5: 1915 | R5: 2456.9 | S5: 2325 | T5: 2283.6 | U5: 147.9 | V5: -57.1 | W5: 387.8 | X5: 1089.5 | Y5: 734.1 | Z5: 1888.9 | AA5: 1811.3 | AB5: 1426.5 | AC5: 1864.8 | AD5: 465.6 | AE5: 2456.8 | AF5: 968.7 | AG5: -26.5 | AH5: 529.5 | AI5: 147.7 | AJ5: 978.5 | AK5: 345.8 | AL5: 865.7 | AM5: 1689.2 | AN5: 615.8 | AO5: 2180 | AP5: 2138 | AQ5: 699 | AR5: 1293.6 | AS5: 2307.8 | AT5: 1049.5 | AU5: 798.4 | AV5: 254.3 | AW5: 2520.3 | AX5: 1251.6 | AY5: 1423.9 | AZ5: 2036.4 | BA5: 531.1 | BB5: 227.7 | BC5: 2502.1 | BD5: 848.7 | BE5: 835.6 | BF5: 2651.9 | BG5: 923.7 | BH5: 1754.5 | BI5: 255.4 | BJ5: 1088.6 | BK5: 1599.5 | BL5: 1719.8 | BM5: 1478.6 | BN5: 2275.2 | BO5: 336 | BP5: 1548.8 | BQ5: 1681.7 | BR5: 198.7 | BS5: 438.7 | BT5: 2478.6 | BU5: 324.2 | BV5: 1859.6 | BW5: 1463.3 | BX5: 2102.8 | BY5: -36.4 | BZ5: 989.8 | CA5: 423.1 | CB5: 1941.8 | CC5: 63.5 | CD5: 276.3 | CE5: 2296.3 | CF5: 1228.6 | CG5: 1092.3 | CH5: 2213.1 | CI5: 1697.7 | CJ5: 2138.8 | CK5: 178.3 | CL5: 2460 | CM5: 3062 | CN5: 1301 | CO5: 647 | CP5: 3140 | CQ5: 623 | CR5: 1086 | CS5: 886 | CT5: 2678 | CU5: 3487 | CV5: 3303 | CW5: 3239 | CX5: 38 | CY5: -266 | CZ5: 396 | DA5: 1448 | DB5: 915 | DC5: 2626 | DD5: 2532 | DE5: 1944 | DF5: 2594 | DG5: 510 | DH5: 3481 | DI5: 1270 | DJ5: -220 | DK5: 605 | DL5: 41 | DM5: 1277 | DN5: 335 | DO5: 1110 | DP5: 2334 | DQ5: 738 | DR5: 3066 | DS5: 3017 | DT5: 869 | DU5: 1747 | DV5: 3263 | DW5: 1379 | DX5: 1011 | DY5: 195 | DZ5: 3590 | EA5: 1685 | EB5: 1956 | EC5: 2874 | ED5: 614 | EE5: 160 | EF5: 3559 | EG5: 1085 | EH5: 1073 | EI5: 3775 | EJ5: 1192 | EK5: 2444 | EL5: 201 | EM5: 1448 | EN5: 2220 | EO5: 2389 | EP5: 2031 | EQ5: 3219 | ER5: 316 | ES5: 2123 | ET5: 2330 | EU5: 112 | EV5: 470 | EW5: 3527 | EX5: 304 | EY5: 2591 | EZ5: 1997 | FA5: 573 | FB5: 305 | FC5: 326 | FD5: 505 | FE5: 1102 | FF5: 1285 | FG5: 622 | FH5: 749 | FI5: 1504 | FJ5: 1190 | FK5: 546 | FL5: 1039 | FM5: 1034 | FN5: 483 | FO5: 552 | FP5: 980 | FQ5: 1677 | FR5: 1841 | FS5: 1771 | FT5: 900 | FU5: -36 | FV5: 60 | FW5: 519 | FX5: 657 | FY5: 977 | FZ5: 1408 | GA5: 1223 | GB5: 1244 | GC5: 860 | GD5: 1097 | GE5: 1298 | GF5: 305 | GG5: 129 | GH5: 199 | GI5: 378 | GJ5: 458 | GK5: 412 | GL5: 950 | GM5: 850 | GN5: 1046 | GO5: 1655 | GP5: 1063 | GQ5: 725 | GR5: 1368 | GS5: 1271 | GT5: 667 | GU5: 349 | GV5: 1038 | GW5: 1437 | GX5: 998 | GY5: 1312 | GZ5: 955 | HA5: 231 | HB5: 1020 | HC5: 1268 | HD5: 602 | HE5: 1323 | HF5: 1358 | HG5: 999 | HH5: 732 | HI5: 465 | HJ5: 1003 | HK5: 1256 | HL5: 1207 | HM5: 1429 | HN5: 972 | HO5: 682 | HP5: 1220 | HQ5: 680 | HR5: 183 | HS5: 1095 | HT5: 1049 | HU5: 801 | HV5: 1257 | HW5: 1354 | HX5: 754 | HY5: 309 | HZ5: 493 | IA5: 874 | IB5: 730 | IC5: 64 | ID5: 957 | IE5: 1338 | IF5: 856 | IG5: 1250 | IH5: 1492 | II5: 1462 | IJ5: 855 | IK5: 983 | IL5: 2137 | IM5: 1673 | IN5: 707 | IO5: 1443 | IP5: 1794
A6: 1195.8 | B6: 397 | C6: 559.7 | D6: 463.2 | E6: 1014.2 | F6: 1905.9 | G6: 1472.7 | H6: 273.3 | I6: 1786.1 | J6: 2177.5 | K6: 989.1 | L6: 572.4 | M6: 2216.9 | N6: 560.1 | O6: 810.4 | P6: 655.4 | Q6: 1905.2 | R6: 2443.5 | S6: 2318 | T6: 2327.6 | U6: 163.3 | V6: -59 | W6: 463.9 | X6: 1094.1 | Y6: 723.5 | Z6: 1891.7 | AA6: 1820.1 | AB6: 1464.4 | AC6: 1886 | AD6: 463.2 | AE6: 2457.7 | AF6: 1012.4 | AG6: 11.1 | AH6: 504.7 | AI6: 188.9 | AJ6: 991.2 | AK6: 338.7 | AL6: 920.7 | AM6: 1655.4 | AN6: 654.3 | AO6: 2202.3 | AP6: 2186.4 | AQ6: 705.8 | AR6: 1332.3 | AS6: 2316.3 | AT6: 1067.5 | AU6: 757.5 | AV6: 258.1 | AW6: 2570.8 | AX6: 1258.8 | AY6: 1425.1 | AZ6: 2088.7 | BA6: 539.5 | BB6: 212.7 | BC6: 2508.1 | BD6: 836.3 | BE6: 834.6 | BF6: 2555 | BG6: 901 | BH6: 1749.2 | BI6: 283.9 | BJ6: 1102 | BK6: 1611.1 | BL6: 1724.2 | BM6: 1467.3 | BN6: 2278.7 | BO6: 340.4 | BP6: 1534.7 | BQ6: 1681.4 | BR6: 234.4 | BS6: 411.2 | BT6: 2463.2 | BU6: 373.2 | BV6: 1871.5 | BW6: 1497.9 | BX6: 2067.8 | BY6: -27.1 | BZ6: 962.9 | CA6: 412.1 | CB6: 1880.7 | CC6: 32.1 | CD6: 275.4 | CE6: 2327 | CF6: 1290 | CG6: 1135 | CH6: 2230.6 | CI6: 1680.9 | CJ6: 2125.6 | CK6: 175.9 | CL6: 2493 | CM6: 3075 | CN6: 1302 | CO6: 675 | CP6: 3129 | CQ6: 653 | CR6: 1031 | CS6: 794 | CT6: 2669 | CU6: 3486 | CV6: 3292 | CW6: 3306 | CX6: 59 | CY6: -271 | CZ6: 510 | DA6: 1460 | DB6: 903 | DC6: 2652 | DD6: 2533 | DE6: 2014 | DF6: 2639 | DG6: 505 | DH6: 3481 | DI6: 1337 | DJ6: -166 | DK6: 574 | DL6: 98 | DM6: 1297 | DN6: 320 | DO6: 1193 | DP6: 2297 | DQ6: 799 | DR6: 3117 | DS6: 3099 | DT6: 877 | DU6: 1808 | DV6: 3289 | DW6: 1412 | DX6: 951 | DY6: 202 | DZ6: 3651 | EA6: 1688 | EB6: 1958 | EC6: 2933 | ED6: 628 | EE6: 136 | EF6: 3561 | EG6: 1073 | EH6: 1066 | EI6: 3624 | EJ6: 1171 | EK6: 2421 | EL6: 240 | EM6: 1465 | EN6: 2216 | EO6: 2401 | EP6: 2008 | EQ6: 3222 | ER6: 328 | ES6: 2103 | ET6: 2326 | EU6: 172 | EV6: 431 | EW6: 3511 | EX6: 378 | EY6: 2612 | EZ6: 2050 | FA6: 565 | FB6: 310 | FC6: 343 | FD6: 525 | FE6: 1096 | FF6: 1279 | FG6: 626 | FH6: 752 | FI6: 1513 | FJ6: 1194 | FK6: 552 | FL6: 1044 | FM6: 1039 | FN6: 476 | FO6: 514 | FP6: 952 | FQ6: 1667 | FR6: 1832 | FS6: 1786 | FT6: 924 | FU6: -30 | FV6: 90 | FW6: 551 | FX6: 655 | FY6: 974 | FZ6: 1413 | GA6: 1242 | GB6: 1268 | GC6: 867 | GD6: 1096 | GE6: 1316 | GF6: 337 | GG6: 134 | GH6: 205 | GI6: 400 | GJ6: 460 | GK6: 432 | GL6: 958 | GM6: 852 | GN6: 1070 | GO6: 1683 | GP6: 1085 | GQ6: 743 | GR6: 1387 | GS6: 1281 | GT6: 658 | GU6: 334 | GV6: 1059 | GW6: 1460 | GX6: 1001 | GY6: 1333 | GZ6: 979 | HA6: 229 | HB6: 1016 | HC6: 1266 | HD6: 596 | HE6: 1284 | HF6: 1310 | HG6: 988 | HH6: 741 | HI6: 482 | HJ6: 1013 | HK6: 1262 | HL6: 1204 | HM6: 1426 | HN6: 975 | HO6: 678 | HP6: 1214 | HQ6: 694 | HR6: 186 | HS6: 1078 | HT6: 1062 | HU6: 826 | HV6: 1276 | HW6: 1354 | HX6: 744 | HY6: 302 | HZ6: 478 | IA6: 845 | IB6: 693 | IC6: 51 | ID6: 969 | IE6: 1375 | IF6: 898 | IG6: 1274 | IH6: 1492 | II6: 1450 | IJ6: 848 | IK6: 995 | IL6: 2155 | IM6: 1679 | IN6: 719 | IO6: 1449 | IP6: 1802
A7: 1136.9 | B7: 394.9 | C7: 585 | D7: 453.5 | E7: 971.9 | F7: 1943.2 | G7: 1450.4 | H7: 280.7 | I7: 1794.7 | J7: 2217.4 | K7: 1015.2 | L7: 573.4 | M7: 2221.1 | N7: 565.1 | O7: 850 | P7: 648 | Q7: 1877 | R7: 2477.4 | S7: 2319.9 | T7: 2307.7 | U7: 169.8 | V7: -40.3 | W7: 405.1 | X7: 1107.6 | Y7: 696 | Z7: 1899.8 | AA7: 1807.2 | AB7: 1509.1 | AC7: 1888.6 | AD7: 453.5 | AE7: 2442.2 | AF7: 1069.8 | AG7: -8.7 | AH7: 551.3 | AI7: 163.2 | AJ7: 984.1 | AK7: 346 | AL7: 901.8 | AM7: 1675.6 | AN7: 621.4 | AO7: 2194.3 | AP7: 2180.5 | AQ7: 696 | AR7: 1331.9 | AS7: 2302.4 | AT7: 1070.2 | AU7: 772.1 | AV7: 259.8 | AW7: 2534.1 | AX7: 1239.4 | AY7: 1466.6 | AZ7: 2022.3 | BA7: 512.8 | BB7: 173.7 | BC7: 2504.5 | BD7: 867.2 | BE7: 837.2 | BF7: 2641.5 | BG7: 931.8 | BH7: 1753.7 | BI7: 266.5 | BJ7: 1194 | BK7: 1585.9 | BL7: 1724.3 | BM7: 1470.6 | BN7: 2284.1 | BO7: 343.7 | BP7: 1542.9 | BQ7: 1700.6 | BR7: 213.3 | BS7: 434.5 | BT7: 2446.9 | BU7: 316.3 | BV7: 1958.5 | BW7: 1491.5 | BX7: 2155.8 | BY7: -27.8 | BZ7: 985.5 | CA7: 416.7 | CB7: 1892.6 | CC7: 39.8 | CD7: 273.9 | CE7: 2304.4 | CF7: 1197.9 | CG7: 1144.6 | CH7: 2257.7 | CI7: 1699.3 | CJ7: 2167.3 | CK7: 179.5 | CL7: 2508 | CM7: 3134 | CN7: 1328 | CO7: 676 | CP7: 3147 | CQ7: 666 | CR7: 1086 | CS7: 784 | CT7: 2625 | CU7: 3535 | CV7: 3277 | CW7: 3282 | CX7: 75 | CY7: -243 | CZ7: 423 | DA7: 1473 | DB7: 852 | DC7: 2649 | DD7: 2526 | DE7: 2067 | DF7: 2645 | DG7: 495 | DH7: 3470 | DI7: 1420 | DJ7: -195 | DK7: 640 | DL7: 59 | DM7: 1295 | DN7: 337 | DO7: 1161 | DP7: 2316 | DQ7: 745 | DR7: 3112 | DS7: 3062 | DT7: 855 | DU7: 1818 | DV7: 3254 | DW7: 1414 | DX7: 969 | DY7: 209 | DZ7: 3595 | EA7: 1663 | EB7: 2010 | EC7: 2834 | ED7: 581 | EE7: 76 | EF7: 3574 | EG7: 1112 | EH7: 1065 | EI7: 3747 | EJ7: 1214 | EK7: 2439 | EL7: 217 | EM7: 1606 | EN7: 2177 | EO7: 2406 | EP7: 2015 | EQ7: 3238 | ER7: 329 | ES7: 2125 | ET7: 2361 | EU7: 138 | EV7: 462 | EW7: 3481 | EX7: 287 | EY7: 2746 | EZ7: 2044 | FA7: 541 | FB7: 320 | FC7: 306 | FD7: 461 | FE7: 1094 | FF7: 1285 | FG7: 620 | FH7: 758 | FI7: 1533 | FJ7: 1221 | FK7: 563 | FL7: 1046 | FM7: 1042 | FN7: 494 | FO7: 527 | FP7: 938 | FQ7: 1670 | FR7: 1847 | FS7: 1779 | FT7: 919 | FU7: -20 | FV7: 74 | FW7: 533 | FX7: 649 | FY7: 966 | FZ7: 1411 | GA7: 1254 | GB7: 1287 | GC7: 865 | GD7: 1086 | GE7: 1333 | GF7: 352 | GG7: 145 | GH7: 214 | GI7: 387 | GJ7: 460 | GK7: 427 | GL7: 959 | GM7: 847 | GN7: 1054 | GO7: 1678 | GP7: 1078 | GQ7: 739 | GR7: 1382 | GS7: 1277 | GT7: 665 | GU7: 341 | GV7: 1045 | GW7: 1437 | GX7: 1010 | GY7: 1323 | GZ7: 942 | HA7: 202 | HB7: 999 | HC7: 1276 | HD7: 610 | HE7: 1319 | HF7: 1357 | HG7: 1002 | HH7: 736 | HI7: 512 | HJ7: 1040 | HK7: 1252 | HL7: 1206 | HM7: 1430 | HN7: 979 | HO7: 682 | HP7: 1225 | HQ7: 693 | HR7: 187 | HS7: 1080 | HT7: 1033 | HU7: 838 | HV7: 1308 | HW7: 1387 | HX7: 779 | HY7: 311 | HZ7: 489 | IA7: 852 | IB7: 701 | IC7: 53 | ID7: 959 | IE7: 1329 | IF7: 865 | IG7: 1289 | IH7: 1511 | II7: 1474 | IJ7: 867 | IK7: 1003 | IL7: 2185 | IM7: 1713 | IN7: 729 | IO7: 1457 | IP7: 1814
A8: 1167.4 | B8: 392.3 | C8: 554.9 | D8: 443.7 | E8: 984.9 | F8: 1928.2 | G8: 1458 | H8: 277.9 | I8: 1784.1 | J8: 2176 | K8: 982.2 | L8: 564.2 | M8: 2220.9 | N8: 540.3 | O8: 833.6 | P8: 695.6 | Q8: 1883.9 | R8: 2483.2 | S8: 2321 | T8: 2338.1 | U8: 242.4 | V8: -47.1 | W8: 457.6 | X8: 1070.8 | Y8: 712 | Z8: 1913.6 | AA8: 1853.1 | AB8: 1455.2 | AC8: 1891.8 | AD8: 443.7 | AE8: 2449.2 | AF8: 991 | AG8: -44.1 | AH8: 530 | AI8: 182.4 | AJ8: 1003 | AK8: 339.6 | AL8: 967.2 | AM8: 1688 | AN8: 633.5 | AO8: 2219.8 | AP8: 2133.4 | AQ8: 707.1 | AR8: 1263.2 | AS8: 2315.4 | AT8: 1073.7 | AU8: 769.2 | AV8: 258.4 | AW8: 2540.2 | AX8: 1245 | AY8: 1410.5 | AZ8: 2024.2 | BA8: 513 | BB8: 210.3 | BC8: 2507.4 | BD8: 867.4 | BE8: 832.2 | BF8: 2623.6 | BG8: 922.9 | BH8: 1758.1 | BI8: 243.2 | BJ8: 1136.5 | BK8: 1595.8 | BL8: 1707.9 | BM8: 1471.4 | BN8: 2263.3 | BO8: 340.4 | BP8: 1542.9 | BQ8: 1706.6 | BR8: 203.4 | BS8: 426.6 | BT8: 2468.5 | BU8: 295.6 | BV8: 1919.6 | BW8: 1482 | BX8: 2136.9 | BY8: -21.4 | BZ8: 976.4 | CA8: 423.6 | CB8: 1907.9 | CC8: 49.9 | CD8: 279.4 | CE8: 2368 | CF8: 1250.4 | CG8: 1075.9 | CH8: 2238.1 | CI8: 1702.3 | CJ8: 2111.1 | CK8: 175.9 | CL8: 2495 | CM8: 3054 | CN8: 1292 | CO8: 664 | CP8: 3150 | CQ8: 628 | CR8: 1064 | CS8: 861 | CT8: 2642 | CU8: 3536 | CV8: 3282 | CW8: 3323 | CX8: 183 | CY8: -252 | CZ8: 506 | DA8: 1422 | DB8: 878 | DC8: 2685 | DD8: 2582 | DE8: 1999 | DF8: 2634 | DG8: 480 | DH8: 3479 | DI8: 1306 | DJ8: -249 | DK8: 615 | DL8: 92 | DM8: 1315 | DN8: 324 | DO8: 1270 | DP8: 2339 | DQ8: 761 | DR8: 3147 | DS8: 2990 | DT8: 874 | DU8: 1696 | DV8: 3279 | DW8: 1419 | DX8: 973 | DY8: 204 | DZ8: 3604 | EA8: 1685 | EB8: 1935 | EC8: 2836 | ED8: 586 | EE8: 130 | EF8: 3546 | EG8: 1118 | EH8: 1058 | EI8: 3755 | EJ8: 1190 | EK8: 2453 | EL8: 180 | EM8: 1511 | EN8: 2192 | EO8: 2379 | EP8: 2011 | EQ8: 3211 | ER8: 329 | ES8: 2117 | ET8: 2368 | EU8: 123 | EV8: 457 | EW8: 3510 | EX8: 258 | EY8: 2689 | EZ8: 2037 | FA8: 552 | FB8: 307 | FC8: 331 | FD8: 503 | FE8: 1093 | FF8: 1282 | FG8: 622 | FH8: 753 | FI8: 1512 | FJ8: 1191 | FK8: 546 | FL8: 1042 | FM8: 1032 | FN8: 477 | FO8: 539 | FP8: 960 | FQ8: 1675 | FR8: 1849 | FS8: 1791 | FT8: 960 | FU8: 6 | FV8: 92 | FW8: 539 | FX8: 641 | FY8: 978 | FZ8: 1434 | GA8: 1251 | GB8: 1267 | GC8: 862 | GD8: 1085 | GE8: 1304 | GF8: 307 | GG8: 122 | GH8: 213 | GI8: 402 | GJ8: 465 | GK8: 451 | GL8: 990 | GM8: 856 | GN8: 1069 | GO8: 1669 | GP8: 1064 | GQ8: 716 | GR8: 1359 | GS8: 1283 | GT8: 665 | GU8: 339 | GV8: 1047 | GW8: 1442 | GX8: 990 | GY8: 1302 | GZ8: 943 | HA8: 217 | HB8: 1015 | HC8: 1278 | HD8: 608 | HE8: 1310 | HF8: 1346 | HG8: 1000 | HH8: 728 | HI8: 480 | HJ8: 1021 | HK8: 1249 | HL8: 1200 | HM8: 1422 | HN8: 969 | HO8: 681 | HP8: 1228 | HQ8: 692 | HR8: 180 | HS8: 1086 | HT8: 1033 | HU8: 814 | HV8: 1288 | HW8: 1375 | HX8: 774 | HY8: 310 | HZ8: 488 | IA8: 860 | IB8: 711 | IC8: 60 | ID8: 987 | IE8: 1375 | IF8: 858 | IG8: 1253 | IH8: 1504 | II8: 1453 | IJ8: 843 | IK8: 996 | IL8: 2147 | IM8: 1666 | IN8: 710 | IO8: 1453 | IP8: 1800
A9: 1209.4 | B9: 392.8 | C9: 569.8 | D9: 459.3 | E9: 989.7 | F9: 1895 | G9: 1444.5 | H9: 278.8 | I9: 1794.8 | J9: 2193.2 | K9: 979.2 | L9: 544.8 | M9: 2214.6 | N9: 560.3 | O9: 823.1 | P9: 649.5 | Q9: 1933 | R9: 2498.6 | S9: 2327.2 | T9: 2268.7 | U9: 191.1 | V9: -55.1 | W9: 428.1 | X9: 1091.2 | Y9: 712.8 | Z9: 1930.6 | AA9: 1865.3 | AB9: 1496.4 | AC9: 1864.4 | AD9: 459.3 | AE9: 2428.5 | AF9: 1029.4 | AG9: -6.2 | AH9: 543.1 | AI9: 174 | AJ9: 1009.1 | AK9: 336.9 | AL9: 924.7 | AM9: 1677.4 | AN9: 636.2 | AO9: 2207.1 | AP9: 2186.7 | AQ9: 699.4 | AR9: 1312 | AS9: 2314.9 | AT9: 1087.4 | AU9: 798.8 | AV9: 264 | AW9: 2538.3 | AX9: 1259.7 | AY9: 1360.5 | AZ9: 2044.6 | BA9: 525.8 | BB9: 193.6 | BC9: 2511.1 | BD9: 847.8 | BE9: 833.1 | BF9: 2615.4 | BG9: 924.1 | BH9: 1744.5 | BI9: 283.3 | BJ9: 1192 | BK9: 1624 | BL9: 1720.8 | BM9: 1465 | BN9: 2264.5 | BO9: 334.8 | BP9: 1521.9 | BQ9: 1673.1 | BR9: 188.3 | BS9: 408.7 | BT9: 2448.3 | BU9: 269 | BV9: 1915.3 | BW9: 1519.4 | BX9: 2036.7 | BY9: -19.4 | BZ9: 972.7 | CA9: 411.9 | CB9: 1957.5 | CC9: 46.4 | CD9: 278.3 | CE9: 2349.7 | CF9: 1268.7 | CG9: 1088.6 | CH9: 2196.8 | CI9: 1696.4 | CJ9: 2139 | CK9: 184.4 | CL9: 2495 | CM9: 3094 | CN9: 1283 | CO9: 634 | CP9: 3126 | CQ9: 659 | CR9: 1055 | CS9: 792 | CT9: 2703 | CU9: 3544 | CV9: 3287 | CW9: 3205 | CX9: 102 | CY9: -264 | CZ9: 453 | DA9: 1451 | DB9: 883 | DC9: 2710 | DD9: 2606 | DE9: 2043 | DF9: 2591 | DG9: 508 | DH9: 3436 | DI9: 1361 | DJ9: -191 | DK9: 632 | DL9: 76 | DM9: 1328 | DN9: 324 | DO9: 1195 | DP9: 2329 | DQ9: 770 | DR9: 3103 | DS9: 3071 | DT9: 864 | DU9: 1781 | DV9: 3290 | DW9: 1451 | DX9: 1011 | DY9: 210 | DZ9: 3596 | EA9: 1693 | EB9: 1857 | EC9: 2887 | ED9: 603 | EE9: 110 | EF9: 3585 | EG9: 1083 | EH9: 1063 | EI9: 3736 | EJ9: 1198 | EK9: 2420 | EL9: 238 | EM9: 1603 | EN9: 2256 | EO9: 2385 | EP9: 2005 | EQ9: 3203 | ER9: 316 | ES9: 2094 | ET9: 2321 | EU9: 100 | EV9: 428 | EW9: 3481 | EX9: 219 | EY9: 2684 | EZ9: 2096 | FA9: 569 | FB9: 313 | FC9: 334 | FD9: 502 | FE9: 1082 | FF9: 1264 | FG9: 617 | FH9: 757 | FI9: 1523 | FJ9: 1197 | FK9: 537 | FL9: 1032 | FM9: 1038 | FN9: 481 | FO9: 517 | FP9: 961 | FQ9: 1700 | FR9: 1858 | FS9: 1766 | FT9: 912 | FU9: -18 | FV9: 77 | FW9: 536 | FX9: 649 | FY9: 985 | FZ9: 1446 | GA9: 1272 | GB9: 1272 | GC9: 857 | GD9: 1083 | GE9: 1311 | GF9: 337 | GG9: 143 | GH9: 215 | GI9: 401 | GJ9: 466 | GK9: 432 | GL9: 969 | GM9: 853 | GN9: 1065 | GO9: 1685 | GP9: 1082 | GQ9: 732 | GR9: 1379 | GS9: 1289 | GT9: 682 | GU9: 353 | GV9: 1049 | GW9: 1447 | GX9: 976 | GY9: 1290 | GZ9: 956 | HA9: 216 | HB9: 1010 | HC9: 1271 | HD9: 600 | HE9: 1307 | HF9: 1344 | HG9: 995 | HH9: 739 | HI9: 518 | HJ9: 1054 | HK9: 1266 | HL9: 1202 | HM9: 1420 | HN9: 968 | HO9: 670 | HP9: 1206 | HQ9: 672 | HR9: 167 | HS9: 1071 | HT9: 1015 | HU9: 802 | HV9: 1302 | HW9: 1350 | HX9: 735 | HY9: 309 | HZ9: 482 | IA9: 876 | IB9: 729 | IC9: 58 | ID9: 979 | IE9: 1375 | IF9: 871 | IG9: 1242 | IH9: 1485 | II9: 1462 | IJ9: 857 | IK9: 1000 | IL9: 2163 | IM9: 1679 | IN9: 695 | IO9: 1432 | IP9: 1803
A10: 1169.5 | B10: 391.7 | C10: 569.6 | D10: 424 | E10: 1026.7 | F10: 1893.6 | G10: 1450.7 | H10: 276.2 | I10: 1781.2 | J10: 2179.7 | K10: 989.7 | L10: 582.9 | M10: 2220.4 | N10: 531.2 | O10: 853 | P10: 703.5 | Q10: 1914.5 | R10: 2503.5 | S10: 2331.4 | T10: 2248.3 | U10: 215.2 | V10: -70.4 | W10: 417.5 | X10: 1085.9 | Y10: 716.4 | Z10: 1894.8 | AA10: 1834.6 | AB10: 1441.2 | AC10: 1873.1 | AD10: 424 | AE10: 2444.3 | AF10: 1007.8 | AG10: -29.5 | AH10: 547.9 | AI10: 153.1 | AJ10: 983 | AK10: 328.9 | AL10: 871.4 | AM10: 1661.2 | AN10: 612.6 | AO10: 2217.4 | AP10: 2162.9 | AQ10: 685.6 | AR10: 1276.3 | AS10: 2306.3 | AT10: 1042.4 | AU10: 857.4 | AV10: 254.3 | AW10: 2546.7 | AX10: 1254.7 | AY10: 1407.8 | AZ10: 2036.5 | BA10: 484 | BB10: 172.8 | BC10: 2499.2 | BD10: 919.7 | BE10: 828.8 | BF10: 2648.6 | BG10: 894.2 | BH10: 1745.3 | BI10: 289.7 | BJ10: 1102.2 | BK10: 1583.1 | BL10: 1710.6 | BM10: 1469.3 | BN10: 2266.6 | BO10: 323.5 | BP10: 1559.1 | BQ10: 1701.5 | BR10: 263.5 | BS10: 423.7 | BT10: 2528.8 | BU10: 339.2 | BV10: 1872.4 | BW10: 1463.2 | BX10: 2076 | BY10: -11.2 | BZ10: 997.5 | CA10: 405.8 | CB10: 1897.2 | CC10: 45.6 | CD10: 279.3 | CE10: 2346.6 | CF10: 1225.4 | CG10: 1151.3 | CH10: 2224.4 | CI10: 1707.2 | CJ10: 2130.2 | CK10: 178.7 | CL10: 2473 | CM10: 3063 | CN10: 1290 | CO10: 694 | CP10: 3139 | CQ10: 614 | CR10: 1092 | CS10: 864 | CT10: 2690 | CU10: 3565 | CV10: 3298 | CW10: 3168 | CX10: 139 | CY10: -289 | CZ10: 444 | DA10: 1434 | DB10: 890 | DC10: 2655 | DD10: 2560 | DE10: 1968 | DF10: 2610 | DG10: 456 | DH10: 3466 | DI10: 1318 | DJ10: -225 | DK10: 642 | DL10: 47 | DM10: 1294 | DN10: 313 | DO10: 1118 | DP10: 2294 | DQ10: 739 | DR10: 3120 | DS10: 3058 | DT10: 837 | DU10: 1723 | DV10: 3279 | DW10: 1371 | DX10: 1094 | DY10: 198 | DZ10: 3633 | EA10: 1698 | EB10: 1918 | EC10: 2859 | ED10: 545 | EE10: 74 | EF10: 3557 | EG10: 1200 | EH10: 1049 | EI10: 3782 | EJ10: 1156 | EK10: 2419 | EL10: 249 | EM10: 1467 | EN10: 2189 | EO10: 2371 | EP10: 2013 | EQ10: 3194 | ER10: 305 | ES10: 2156 | ET10: 2370 | EU10: 214 | EV10: 451 | EW10: 3611 | EX10: 322 | EY10: 2612 | EZ10: 2002 | FA10: 552 | FB10: 312 | FC10: 327 | FD10: 510 | FE10: 1096 | FF10: 1266 | FG10: 619 | FH10: 751 | FI10: 1512 | FJ10: 1196 | FK10: 557 | FL10: 1049 | FM10: 1028 | FN10: 481 | FO10: 550 | FP10: 975 | FQ10: 1695 | FR10: 1862 | FS10: 1760 | FT10: 913 | FU10: -14 | FV10: 67 | FW10: 529 | FX10: 649 | FY10: 972 | FZ10: 1420 | GA10: 1238 | GB10: 1254 | GC10: 847 | GD10: 1075 | GE10: 1309 | GF10: 319 | GG10: 135 | GH10: 208 | GI10: 382 | GJ10: 453 | GK10: 408 | GL10: 941 | GM10: 837 | GN10: 1060 | GO10: 1680 | GP10: 1067 | GQ10: 713 | GR10: 1361 | GS10: 1267 | GT10: 688 | GU10: 372 | GV10: 1048 | GW10: 1448 | GX10: 993 | GY10: 1306 | GZ10: 936 | HA10: 191 | HB10: 997 | HC10: 1295 | HD10: 627 | HE10: 1319 | HF10: 1345 | HG10: 984 | HH10: 742 | HI10: 485 | HJ10: 1002 | HK10: 1245 | HL10: 1200 | HM10: 1422 | HN10: 964 | HO10: 681 | HP10: 1232 | HQ10: 714 | HR10: 203 | HS10: 1109 | HT10: 1075 | HU10: 812 | HV10: 1262 | HW10: 1343 | HX10: 754 | HY10: 322 | HZ10: 489 | IA10: 849 | IB10: 705 | IC10: 58 | ID10: 978 | IE10: 1357 | IF10: 878 | IG10: 1278 | IH10: 1500 | II10: 1463 | IJ10: 851 | IK10: 988 | IL10: 2142 | IM10: 1669 | IN10: 721 | IO10: 1461 | IP10: 1790
A11: 1167 | B11: 391.8 | C11: 533.5 | D11: 444.5 | E11: 1029.3 | F11: 1930.6 | G11: 1437.9 | H11: 276.9 | I11: 1794.8 | J11: 2200.4 | K11: 990.4 | L11: 561.4 | M11: 2218.5 | N11: 561.2 | O11: 830 | P11: 627.3 | Q11: 1909.2 | R11: 2484.5 | S11: 2324.1 | T11: 2254.9 | U11: 205.4 | V11: -56.8 | W11: 389.7 | X11: 1099.2 | Y11: 723 | Z11: 1927.3 | AA11: 1751 | AB11: 1414.7 | AC11: 1873.7 | AD11: 444.5 | AE11: 2459.1 | AF11: 1005.1 | AG11: -32.9 | AH11: 543 | AI11: 154.7 | AJ11: 990.4 | AK11: 315.3 | AL11: 872.2 | AM11: 1675 | AN11: 641.6 | AO11: 2196.9 | AP11: 2155.4 | AQ11: 701 | AR11: 1316.6 | AS11: 2307.8 | AT11: 1043.7 | AU11: 800.7 | AV11: 262.4 | AW11: 2520.8 | AX11: 1252.4 | AY11: 1391.4 | AZ11: 2032.5 | BA11: 536.2 | BB11: 168.4 | BC11: 2503.7 | BD11: 892 | BE11: 833.5 | BF11: 2618.7 | BG11: 942.6 | BH11: 1752.5 | BI11: 272.7 | BJ11: 1153.1 | BK11: 1620.3 | BL11: 1720.3 | BM11: 1476.9 | BN11: 2271.1 | BO11: 325.9 | BP11: 1528.7 | BQ11: 1702.1 | BR11: 231.1 | BS11: 409.2 | BT11: 2439.6 | BU11: 333.8 | BV11: 1915.1 | BW11: 1434.3 | BX11: 2126.1 | BY11: -61.2 | BZ11: 951.1 | CA11: 415.9 | CB11: 1912.9 | CC11: 76.4 | CD11: 275.6 | CE11: 2354.5 | CF11: 1310.1 | CG11: 1095.2 | CH11: 2273.8 | CI11: 1696.5 | CJ11: 2130.7 | CK11: 178.4 | CL11: 2502 | CM11: 3099 | CN11: 1297 | CO11: 651 | CP11: 3125 | CQ11: 652 | CR11: 1058 | CS11: 756 | CT11: 2676 | CU11: 3519 | CV11: 3306 | CW11: 3171 | CX11: 125 | CY11: -266 | CZ11: 401 | DA11: 1455 | DB11: 893 | DC11: 2693 | DD11: 2428 | DE11: 1935 | DF11: 2630 | DG11: 480 | DH11: 3475 | DI11: 1317 | DJ11: -231 | DK11: 627 | DL11: 48 | DM11: 1303 | DN11: 293 | DO11: 1120 | DP11: 2318 | DQ11: 775 | DR11: 3089 | DS11: 3033 | DT11: 866 | DU11: 1786 | DV11: 3257 | DW11: 1377 | DX11: 1014 | DY11: 211 | DZ11: 3588 | EA11: 1679 | EB11: 1899 | EC11: 2862 | ED11: 620 | EE11: 69 | EF11: 3544 | EG11: 1155 | EH11: 1071 | EI11: 3743 | EJ11: 1223 | EK11: 2430 | EL11: 229 | EM11: 1532 | EN11: 2250 | EO11: 2399 | EP11: 2031 | EQ11: 3216 | ER11: 307 | ES11: 2104 | ET11: 2360 | EU11: 162 | EV11: 429 | EW11: 3446 | EX11: 315 | EY11: 2678 | EZ11: 1955 | FA11: 551 | FB11: 298 | FC11: 342 | FD11: 541 | FE11: 1112 | FF11: 1275 | FG11: 614 | FH11: 756 | FI11: 1526 | FJ11: 1204 | FK11: 549 | FL11: 1040 | FM11: 1040 | FN11: 484 | FO11: 511 | FP11: 942 | FQ11: 1685 | FR11: 1851 | FS11: 1759 | FT11: 912 | FU11: -13 | FV11: 61 | FW11: 523 | FX11: 657 | FY11: 988 | FZ11: 1399 | GA11: 1194 | GB11: 1243 | GC11: 855 | GD11: 1089 | GE11: 1313 | GF11: 317 | GG11: 132 | GH11: 207 | GI11: 386 | GJ11: 450 | GK11: 403 | GL11: 947 | GM11: 854 | GN11: 1063 | GO11: 1669 | GP11: 1070 | GQ11: 735 | GR11: 1378 | GS11: 1268 | GT11: 666 | GU11: 353 | GV11: 1041 | GW11: 1437 | GX11: 985 | GY11: 1297 | GZ11: 955 | HA11: 210 | HB11: 997 | HC11: 1286 | HD11: 618 | HE11: 1309 | HF11: 1352 | HG11: 1006 | HH11: 738 | HI11: 498 | HJ11: 1037 | HK11: 1264 | HL11: 1207 | HM11: 1427 | HN11: 967 | HO11: 670 | HP11: 1220 | HQ11: 701 | HR11: 184 | HS11: 1067 | HT11: 1037 | HU11: 827 | HV11: 1268 | HW11: 1352 | HX11: 754 | HY11: 284 | HZ11: 475 | IA11: 859 | IB11: 724 | IC11: 69 | ID11: 980 | IE11: 1394 | IF11: 890 | IG11: 1275 | IH11: 1516 | II11: 1459 | IJ11: 851 | IK11: 1000 | IL11: 2168 | IM11: 1686 | IN11: 707 | IO11: 1438 | IP11: 1800
A12: 1150 | B12: 394.1 | C12: 555.1 | D12: 443.4 | E12: 991.7 | F12: 1925.6 | G12: 1476.4 | H12: 278.3 | I12: 1774.1 | J12: 2179.8 | K12: 1000.9 | L12: 554.3 | M12: 2221.5 | N12: 545.2 | O12: 851.5 | P12: 697.4 | Q12: 1918.8 | R12: 2467.5 | S12: 2327.2 | T12: 2296.9 | U12: 208.6 | V12: -54.8 | W12: 444.9 | X12: 1068.3 | Y12: 718.3 | Z12: 1884.2 | AA12: 1821.9 | AB12: 1456.2 | AC12: 1868.7 | AD12: 443.4 | AE12: 2461.6 | AF12: 1004.2 | AG12: -37.4 | AH12: 512.4 | AI12: 153.2 | AJ12: 983.2 | AK12: 341.8 | AL12: 907.3 | AM12: 1683.5 | AN12: 620.6 | AO12: 2224.3 | AP12: 2144.3 | AQ12: 702.1 | AR12: 1277.5 | AS12: 2328.9 | AT12: 1048.6 | AU12: 822.1 | AV12: 262.1 | AW12: 2531.8 | AX12: 1254.2 | AY12: 1433.4 | AZ12: 2041.5 | BA12: 546.9 | BB12: 223.5 | BC12: 2501.4 | BD12: 876.6 | BE12: 831.6 | BF12: 2621.6 | BG12: 914.2 | BH12: 1735 | BI12: 255 | BJ12: 1180.8 | BK12: 1573.1 | BL12: 1726.4 | BM12: 1470.1 | BN12: 2291.7 | BO12: 346.5 | BP12: 1552.9 | BQ12: 1683 | BR12: 213.8 | BS12: 420.4 | BT12: 2468.5 | BU12: 341.3 | BV12: 1921 | BW12: 1484.9 | BX12: 2104.3 | BY12: 41.9 | BZ12: 1009.2 | CA12: 421.9 | CB12: 1877.4 | CC12: 51.7 | CD12: 274.8 | CE12: 2331.8 | CF12: 1280.3 | CG12: 1087.5 | CH12: 2279.3 | CI12: 1701.1 | CJ12: 2114.2 | CK12: 179.2 | CL12: 2479 | CM12: 3067 | CN12: 1315 | CO12: 644 | CP12: 3148 | CQ12: 637 | CR12: 1091 | CS12: 855 | CT12: 2687 | CU12: 3508 | CV12: 3284 | CW12: 3258 | CX12: 127 | CY12: -263 | CZ12: 487 | DA12: 1421 | DB12: 885 | DC12: 2643 | DD12: 2543 | DE12: 1999 | DF12: 2614 | DG12: 483 | DH12: 3505 | DI12: 1313 | DJ12: -239 | DK12: 580 | DL12: 48 | DM12: 1288 | DN12: 332 | DO12: 1173 | DP12: 2337 | DQ12: 749 | DR12: 3127 | DS12: 3037 | DT12: 863 | DU12: 1726 | DV12: 3310 | DW12: 1393 | DX12: 1039 | DY12: 209 | DZ12: 3594 | EA12: 1683 | EB12: 1964 | EC12: 2868 | ED12: 636 | EE12: 154 | EF12: 3567 | EG12: 1128 | EH12: 1062 | EI12: 3723 | EJ12: 1190 | EK12: 2401 | EL12: 202 | EM12: 1590 | EN12: 2165 | EO12: 2398 | EP12: 2012 | EQ12: 3226 | ER12: 333 | ES12: 2142 | ET12: 2327 | EU12: 139 | EV12: 446 | EW12: 3492 | EX12: 329 | EY12: 2693 | EZ12: 2026 | FA12: 545 | FB12: 307 | FC12: 332 | FD12: 507 | FE12: 1095 | FF12: 1289 | FG12: 630 | FH12: 749 | FI12: 1509 | FJ12: 1200 | FK12: 550 | FL12: 1038 | FM12: 1034 | FN12: 486 | FO12: 547 | FP12: 974 | FQ12: 1682 | FR12: 1846 | FS12: 1777 | FT12: 930 | FU12: -11 | FV12: 84 | FW12: 533 | FX12: 642 | FY12: 969 | FZ12: 1410 | GA12: 1239 | GB12: 1258 | GC12: 853 | GD12: 1090 | GE12: 1314 | GF12: 315 | GG12: 118 | GH12: 194 | GI12: 382 | GJ12: 458 | GK12: 427 | GL12: 964 | GM12: 849 | GN12: 1066 | GO12: 1675 | GP12: 1066 | GQ12: 720 | GR12: 1370 | GS12: 1279 | GT12: 676 | GU12: 361 | GV12: 1045 | GW12: 1442 | GX12: 1003 | GY12: 1318 | GZ12: 963 | HA12: 236 | HB12: 1018 | HC12: 1279 | HD12: 611 | HE12: 1309 | HF12: 1342 | HG12: 987 | HH12: 724 | HI12: 502 | HJ12: 1029 | HK12: 1248 | HL12: 1206 | HM12: 1433 | HN12: 983 | HO12: 688 | HP12: 1222 | HQ12: 687 | HR12: 181 | HS12: 1083 | HT12: 1052 | HU12: 833 | HV12: 1290 | HW12: 1363 | HX12: 786 | HY12: 348 | HZ12: 500 | IA12: 848 | IB12: 699 | IC12: 58 | ID12: 970 | IE12: 1373 | IF12: 875 | IG12: 1275 | IH12: 1520 | II12: 1454 | IJ12: 845 | IK12: 991 | IL12: 2146 | IM12: 1681 | IN12: 711 | IO12: 1445 | IP12: 1803
A13: 1180.8 | B13: 394.6 | C13: 569.5 | D13: 429.5 | E13: 1005.6 | F13: 1917.4 | G13: 1453.6 | H13: 282.4 | I13: 1768 | J13: 2193.4 | K13: 1030.2 | L13: 538.1 | M13: 2216.6 | N13: 554.3 | O13: 876.1 | P13: 657 | Q13: 1925.7 | R13: 2527.5 | S13: 2324.8 | T13: 2270.2 | U13: 181.7 | V13: -53.4 | W13: 395.5 | X13: 1088.3 | Y13: 708.2 | Z13: 1890.1 | AA13: 1822.2 | AB13: 1445.2 | AC13: 1827.5 | AD13: 429.5 | AE13: 2442.2 | AF13: 999.5 | AG13: 0.8 | AH13: 580.2 | AI13: 174.5 | AJ13: 993.7 | AK13: 338.3 | AL13: 932.6 | AM13: 1671.8 | AN13: 628.4 | AO13: 2216.5 | AP13: 2156 | AQ13: 702.1 | AR13: 1280.4 | AS13: 2339.1 | AT13: 1064.6 | AU13: 840.5 | AV13: 261.1 | AW13: 2536.6 | AX13: 1247.6 | AY13: 1485.1 | AZ13: 2020.6 | BA13: 543.4 | BB13: 217.6 | BC13: 2507.4 | BD13: 867.9 | BE13: 833.2 | BF13: 2587.7 | BG13: 932.2 | BH13: 1727.7 | BI13: 245.7 | BJ13: 1132.8 | BK13: 1575.2 | BL13: 1733.2 | BM13: 1462.9 | BN13: 2265.4 | BO13: 337 | BP13: 1532.6 | BQ13: 1679.1 | BR13: 177.5 | BS13: 425.8 | BT13: 2425.7 | BU13: 282.3 | BV13: 1910.9 | BW13: 1397.6 | BX13: 2097 | BY13: -56.8 | BZ13: 976.7 | CA13: 414.9 | CB13: 1931.7 | CC13: 102.4 | CD13: 275.9 | CE13: 2313.9 | CF13: 1321.3 | CG13: 1089.6 | CH13: 2248.5 | CI13: 1715.4 | CJ13: 2140.3 | CK13: 182.2 | CL13: 2447 | CM13: 3102 | CN13: 1365 | CO13: 618 | CP13: 3127 | CQ13: 641 | CR13: 1130 | CS13: 799 | CT13: 2706 | CU13: 3600 | CV13: 3291 | CW13: 3209 | CX13: 89 | CY13: -263 | CZ13: 410 | DA13: 1450 | DB13: 882 | DC13: 2634 | DD13: 2549 | DE13: 1987 | DF13: 2554 | DG13: 458 | DH13: 3482 | DI13: 1318 | DJ13: -178 | DK13: 683 | DL13: 81 | DM13: 1304 | DN13: 322 | DO13: 1203 | DP13: 2323 | DQ13: 758 | DR13: 3114 | DS13: 3050 | DT13: 868 | DU13: 1730 | DV13: 3297 | DW13: 1400 | DX13: 1070 | DY13: 209 | DZ13: 3617 | EA13: 1689 | EB13: 2048 | EC13: 2851 | ED13: 634 | EE13: 141 | EF13: 3555 | EG13: 1119 | EH13: 1069 | EI13: 3667 | EJ13: 1208 | EK13: 2398 | EL13: 187 | EM13: 1501 | EN13: 2181 | EO13: 2398 | EP13: 1995 | EQ13: 3206 | ER13: 324 | ES13: 2098 | ET13: 2320 | EU13: 84 | EV13: 453 | EW13: 3426 | EX13: 243 | EY13: 2682 | EZ13: 1909 | FA13: 558 | FB13: 313 | FC13: 330 | FD13: 505 | FE13: 1097 | FF13: 1276 | FG13: 622 | FH13: 748 | FI13: 1512 | FJ13: 1217 | FK13: 555 | FL13: 1030 | FM13: 1036 | FN13: 500 | FO13: 541 | FP13: 961 | FQ13: 1709 | FR13: 1869 | FS13: 1766 | FT13: 909 | FU13: -21 | FV13: 65 | FW13: 521 | FX13: 646 | FY13: 967 | FZ13: 1413 | GA13: 1235 | GB13: 1237 | GC13: 831 | GD13: 1076 | GE13: 1304 | GF13: 328 | GG13: 160 | GH13: 230 | GI13: 395 | GJ13: 461 | GK13: 436 | GL13: 970 | GM13: 848 | GN13: 1066 | GO13: 1677 | GP13: 1071 | GQ13: 721 | GR13: 1376 | GS13: 1289 | GT13: 690 | GU13: 368 | GV13: 1047 | GW13: 1441 | GX13: 1021 | GY13: 1330 | GZ13: 953 | HA13: 232 | HB13: 1018 | HC13: 1278 | HD13: 608 | HE13: 1296 | HF13: 1336 | HG13: 992 | HH13: 717 | HI13: 479 | HJ13: 1011 | HK13: 1251 | HL13: 1206 | HM13: 1419 | HN13: 969 | HO13: 676 | HP13: 1212 | HQ13: 670 | HR13: 169 | HS13: 1068 | HT13: 1011 | HU13: 805 | HV13: 1251 | HW13: 1326 | HX13: 744 | HY13: 296 | HZ13: 484 | IA13: 866 | IB13: 741 | IC13: 79 | ID13: 964 | IE13: 1382 | IF13: 892 | IG13: 1263 | IH13: 1513 | II13: 1470 | IJ13: 857 | IK13: 979 | IL13: 2147 | IM13: 1715 | IN13: 721 | IO13: 1426 | IP13: 1796
... A201: 1193.2 | B201: 391.1 | C201: 578.9 | D201: 472.3 | E201: 988.1 | F201: 1908.9 | G201: 1451.1 | H201: 276.7 | I201: 1776.7 | J201: 2185.1 | K201: 996.1 | L201: 562.2 | M201: 2215.4 | N201: 554.9 | O201: 852.2 | P201: 667.1 | Q201: 1890.7 | R201: 2469.3 | S201: 2316.9 | T201: 2364.6 | U201: 208.1 | V201: -55 | W201: 431.6 | X201: 1099 | Y201: 717 | Z201: 1898.5 | AA201: 1819.1 | AB201: 1464 | AC201: 1898.8 | AD201: 472.3 | AE201: 2428.4 | AF201: 1010.7 | AG201: -9.9 | AH201: 511 | AI201: 165.8 | AJ201: 996 | AK201: 338.7 | AL201: 890.2 | AM201: 1665.9 | AN201: 631 | AO201: 2200.2 | AP201: 2151.2 | AQ201: 700.7 | AR201: 1338.7 | AS201: 2327.5 | AT201: 1034.8 | AU201: 813.6 | AV201: 250.3 | AW201: 2528.4 | AX201: 1245.5 | AY201: 1405.7 | AZ201: 2080.5 | BA201: 511.6 | BB201: 211.5 | BC201: 2504.6 | BD201: 855 | BE201: 834.1 | BF201: 2637 | BG201: 932.2 | BH201: 1767.3 | BI201: 265.5 | BJ201: 1124.2 | BK201: 1549.6 | BL201: 1700.7 | BM201: 1473.4 | BN201: 2266 | BO201: 338.4 | BP201: 1540.1 | BQ201: 1696.4 | BR201: 264.4 | BS201: 431.7 | BT201: 2432 | BU201: 322.4 | BV201: 1888.4 | BW201: 1394.3 | BX201: 2096.9 | BY201: -3.2 | BZ201: 952.8 | CA201: 413.1 | CB201: 1928.5 | CC201: 67.1 | CD201: 270.5 | CE201: 2349.9 | CF201: 1296.4 | CG201: 1123.6 | CH201: 2217.4 | CI201: 1706.7 | CJ201: 2129.3 | CK201: 182 | CL201: 2481 | CM201: 3068 | CN201: 1309 | CO201: 662 | CP201: 3130 | CQ201: 648 | CR201: 1093 | CS201: 816 | CT201: 2632 | CU201: 3511 | CV201: 3271 | CW201: 3353 | CX201: 127 | CY201: -264 | CZ201: 461 | DA201: 1458 | DB201: 894 | DC201: 2657 | DD201: 2535 | DE201: 2004 | DF201: 2656 | DG201: 526 | DH201: 3462 | DI201: 1324 | DJ201: -197 | DK201: 578 | DL201: 68 | DM201: 1301 | DN201: 328 | DO201: 1144 | DP201: 2315 | DQ201: 755 | DR201: 3093 | DS201: 3016 | DT201: 863 | DU201: 1828 | DV201: 3310 | DW201: 1363 | DX201: 1041 | DY201: 191 | DZ201: 3593 | EA201: 1688 | EB201: 1922 | EC201: 2931 | ED201: 579 | EE201: 134 | EF201: 3561 | EG201: 1090 | EH201: 1063 | EI201: 3772 | EJ201: 1209 | EK201: 2462 | EL201: 217 | EM201: 1502 | EN201: 2135 | EO201: 2346 | EP201: 2011 | EQ201: 3200 | ER201: 325 | ES201: 2128 | ET201: 2349 | EU201: 217 | EV201: 467 | EW201: 3442 | EX201: 302 | EY201: 2651 | EZ201: 1892 | FA201: 562 | FB201: 316 | FC201: 331 | FD201: 495 | FE201: 1087 | FF201: 1272 | FG201: 619 | FH201: 749 | FI201: 1513 | FJ201: 1200 | FK201: 551 | FL201: 1039 | FM201: 1036 | FN201: 491 | FO201: 536 | FP201: 951 | FQ201: 1672 | FR201: 1842 | FS201: 1800 | FT201: 957 | FU201: -11 | FV201: 78 | FW201: 540 | FX201: 654 | FY201: 974 | FZ201: 1415 | GA201: 1241 | GB201: 1273 | GC201: 876 | GD201: 1088 | GE201: 1303 | GF201: 328 | GG201: 128 | GH201: 199 | GI201: 393 | GJ201: 462 | GK201: 419 | GL201: 950 | GM201: 847 | GN201: 1060 | GO201: 1668 | GP201: 1069 | GQ201: 744 | GR201: 1394 | GS201: 1273 | GT201: 667 | GU201: 353 | GV201: 1039 | GW201: 1437 | GX201: 988 | GY201: 1322 | GZ201: 965 | HA201: 217 | HB201: 1014 | HC201: 1272 | HD201: 603 | HE201: 1316 | HF201: 1355 | HG201: 1008 | HH201: 741 | HI201: 484 | HJ201: 997 | HK201: 1228 | HL201: 1197 | HM201: 1424 | HN201: 970 | HO201: 679 | HP201: 1222 | HQ201: 712 | HR201: 206 | HS201: 1073 | HT201: 1030 | HU201: 812 | HV201: 1241 | HW201: 1324 | HX201: 765 | HY201: 308 | HZ201: 474 | IA201: 864 | IB201: 726 | IC201: 63 | ID201: 976 | IE201: 1386 | IF201: 896 | IG201: 1264 | IH201: 1497 | II201: 1462 | IJ201: 852 | IK201: 993 | IL201: 2147 | IM201: 1679 | IN201: 716 | IO201: 1445 | IP201: 1800

Sheet histogram
A1: v215 | B1: data | D1: Max | E1: Min | F1: Range | G1: Delta | H1: Begin point | I1: N | J1: Xсред | K1: Sв | L1: Median | M1: Mode | Q1: n | S1: Хср | V1: s^2 | W1: s
A2: 1 | B2: =HLOOKUP($A$1,data!$A$1:$IP$201,A2+1,0) -> 986 | J2: 994.91 | M2: =(1/Q2)*SUM(Q5:Q15) -> 102.5919 | N2: =SQRT(M2) -> 10.128766 | O2: =N2/J2 -> 0.010180585 | Q2: 200 | S2: =(1/200)*SUM(__Anonymous_Sheet_DB__1[[#All],[Столбец1]]) -> 994.645 | T2: =__Anonymous_Sheet_DB__1[[#This Row],[Столбец1]]*__Anonymous_Sheet_DB__1[[#This Row],[Столбец1]] -> 972196 | U2: =(1/200)*SUM(T2:T201) -> 989416.02 | V2: =U2-S3 -> 97.338975 | W2: =SQRT(V2) -> 9.8660516 | X2: =200*V2/200-1 -> 96.338975 | Y2: =SQRT(X2) -> 9.815242
A3: 2 | B3: =HLOOKUP($A$1,data!$A$1:$IP$201,A3+1,0) -> 990 | S3: =S2*S2 -> 989318.68 | T3: =__Anonymous_Sheet_DB__1[[#This Row],[Столбец1]]*__Anonymous_Sheet_DB__1[[#This Row],[Столбец1]] -> 980100
A4: 3 | B4: =HLOOKUP($A$1,data!$A$1:$IP$201,A4+1,0) -> 988 | D4: Interval N | E4: Begin | F4: End | G4: Xi | H4: Fi | I4: Fi / N | J4: acc Fi / N | T4: =__Anonymous_Sheet_DB__1[[#This Row],[Столбец1]]*__Anonymous_Sheet_DB__1[[#This Row],[Столбец1]] -> 976144
A5: 4 | B5: =HLOOKUP($A$1,data!$A$1:$IP$201,A5+1,0) -> 999 | D5: 1 | E5: 965 | F5: 971 | G5: 968 | H5: 1 | I5: 0.005 | J5: 0.005 | Q5: =H5*(G5-$J$2)^2 -> 724.1481 | R5: =((G5-$J$2)^4)*(H5) -> 524390.47 | T5: =__Anonymous_Sheet_DB__1[[#This Row],[Столбец1]]*__Anonymous_Sheet_DB__1[[#This Row],[Столбец1]] -> 998001
A6: 5 | B6: =HLOOKUP($A$1,data!$A$1:$IP$201,A6+1,0) -> 988 | D6: 2 | E6: 971 | F6: 977 | G6: 974 | H6: 8 | I6: 0.04 | J6: 0.045 | Q6: =H6*(G6-$J$2)^2 -> 3497.8248 | R6: =((G6-$J$2)^4)*(H6) -> 1529347.3 | T6: =__Anonymous_Sheet_DB__1[[#This Row],[Столбец1]]*__Anonymous_Sheet_DB__1[[#This Row],[Столбец1]] -> 976144
A7: 6 | B7: =HLOOKUP($A$1,data!$A$1:$IP$201,A7+1,0) -> 1002 | D7: 3 | E7: 977 | F7: 983 | G7: 980 | H7: 14 | I7: 0.07 | J7: 0.115 | Q7: =H7*(G7-$J$2)^2 -> 3112.3134 | R7: =((G7-$J$2)^4)*(H7) -> 691892.48 | T7: =__Anonymous_Sheet_DB__1[[#This Row],[Столбец1]]*__Anonymous_Sheet_DB__1[[#This Row],[Столбец1]] -> 1004004
A8: 7 | B8: =HLOOKUP($A$1,data!$A$1:$IP$201,A8+1,0) -> 1000 | D8: 4 | E8: 983 | F8: 989 | G8: 986 | H8: 35 | I8: 0.175 | J8: 0.29 | Q8: =H8*(G8-$J$2)^2 -> 2778.5835 | R8: =((G8-$J$2)^4)*(H8) -> 220586.46 | T8: =__Anonymous_Sheet_DB__1[[#This Row],[Столбец1]]*__Anonymous_Sheet_DB__1[[#This Row],[Столбец1]] -> 1000000
A9: 8 | B9: =HLOOKUP($A$1,data!$A$1:$IP$201,A9+1,0) -> 995 | D9: 5 | E9: 989 | F9: 995 | G9: 992 | H9: 40 | I9: 0.2 | J9: 0.49 | Q9: =H9*(G9-$J$2)^2 -> 338.724 | R9: =((G9-$J$2)^4)*(H9) -> 2868.3487 | T9: =__Anonymous_Sheet_DB__1[[#This Row],[Столбец1]]*__Anonymous_Sheet_DB__1[[#This Row],[Столбец1]] -> 990025
A10: 9 | B10: =HLOOKUP($A$1,data!$A$1:$IP$201,A10+1,0) -> 984 | D10: 6 | E10: 995 | F10: 1001 | G10: 998 | H10: 44 | I10: 0.22 | J10: 0.71 | Q10: =H10*(G10-$J$2)^2 -> 420.1164 | R10: =((G10-$J$2)^4)*(H10) -> 4011.3134 | T10: =__Anonymous_Sheet_DB__1[[#This Row],[Столбец1]]*__Anonymous_Sheet_DB__1[[#This Row],[Столбец1]] -> 968256
A11: 10 | B11: =HLOOKUP($A$1,data!$A$1:$IP$201,A11+1,0) -> 1006 | D11: 7 | E11: 1001 | F11: 1007 | G11: 1004 | H11: 37 | I11: 0.185 | J11: 0.895 | Q11: =H11*(G11-$J$2)^2 -> 3057.2397 | R11: =((G11-$J$2)^4)*(H11) -> 252613.91 | T11: =__Anonymous_Sheet_DB__1[[#This Row],[Столбец1]]*__Anonymous_Sheet_DB__1[[#This Row],[Столбец1]] -> 1012036
A12: 11 | B12: =HLOOKUP($A$1,data!$A$1:$IP$201,A12+1,0) -> 987 | D12: 8 | E12: 1007 | F12: 1013 | G12: 1010 | H12: 17 | I12: 0.085 | J12: 0.98 | Q12: =H12*(G12-$J$2)^2 -> 3871.0377 | R12: =((G12-$J$2)^4)*(H12) -> 881466.64 | T12: =__Anonymous_Sheet_DB__1[[#This Row],[Столбец1]]*__Anonymous_Sheet_DB__1[[#This Row],[Столбец1]] -> 974169
A13: 12 | B13: =HLOOKUP($A$1,data!$A$1:$IP$201,A13+1,0) -> 992 | D13: 9 | E13: 1013 | F13: 1019 | G13: 1016 | H13: 2 | I13: 0.01 | J13: 0.99 | Q13: =H13*(G13-$J$2)^2 -> 889.5762 | R13: =((G13-$J$2)^4)*(H13) -> 395672.91 | T13: =__Anonymous_Sheet_DB__1[[#This Row],[Столбец1]]*__Anonymous_Sheet_DB__1[[#This Row],[Столбец1]] -> 984064
A14: 13 | B14: =HLOOKUP($A$1,data!$A$1:$IP$201,A14+1,0) -> 1008 | D14: 10 | E14: 1019 | F14: 1025 | G14: 1022 | H14: 1 | I14: 0.005 | J14: 0.995 | Q14: =H14*(G14-$J$2)^2 -> 733.8681 | R14: =((G14-$J$2)^4)*(H14) -> 538562.39 | T14: =__Anonymous_Sheet_DB__1[[#This Row],[Столбец1]]*__Anonymous_Sheet_DB__1[[#This Row],[Столбец1]] -> 1016064
A15: 14 | B15: =HLOOKUP($A$1,data!$A$1:$IP$201,A15+1,0) -> 998 | D15: 11 | E15: 1025 | F15: 1031 | G15: 1028 | H15: 1 | I15: 0.005 | J15: 1 | Q15: =H15*(G15-$J$2)^2 -> 1094.9481 | R15: =((G15-$J$2)^4)*(H15) -> 1198911.3 | T15: =__Anonymous_Sheet_DB__1[[#This Row],[Столбец1]]*__Anonymous_Sheet_DB__1[[#This Row],[Столбец1]] -> 996004
A16: 15 | B16: =HLOOKUP($A$1,data!$A$1:$IP$201,A16+1,0) -> 1000 | G16: Sum: | H16: =SUM(H5:H15) -> 200 | I16: =SUM(I5:I15) -> 1 | T16: =__Anonymous_Sheet_DB__1[[#This Row],[Столбец1]]*__Anonymous_Sheet_DB__1[[#This Row],[Столбец1]] -> 1000000
A17: 16 | B17: =HLOOKUP($A$1,data!$A$1:$IP$201,A17+1,0) -> 981 | T17: =__Anonymous_Sheet_DB__1[[#This Row],[Столбец1]]*__Anonymous_Sheet_DB__1[[#This Row],[Столбец1]] -> 962361
A18: 17 | B18: =HLOOKUP($A$1,data!$A$1:$IP$201,A18+1,0) -> 1004 | T18: =__Anonymous_Sheet_DB__1[[#This Row],[Столбец1]]*__Anonymous_Sheet_DB__1[[#This Row],[Столбец1]] -> 1008016
A19: 18 | B19: =HLOOKUP($A$1,data!$A$1:$IP$201,A19+1,0) -> 988 | T19: =__Anonymous_Sheet_DB__1[[#This Row],[Столбец1]]*__Anonymous_Sheet_DB__1[[#This Row],[Столбец1]] -> 976144
A20: 19 | B20: =HLOOKUP($A$1,data!$A$1:$IP$201,A20+1,0) -> 999 | T20: =__Anonymous_Sheet_DB__1[[#This Row],[Столбец1]]*__Anonymous_Sheet_DB__1[[#This Row],[Столбец1]] -> 998001
A21: 20 | B21: =HLOOKUP($A$1,data!$A$1:$IP$201,A21+1,0) -> 1003 | T21: =__Anonymous_Sheet_DB__1[[#This Row],[Столбец1]]*__Anonymous_Sheet_DB__1[[#This Row],[Столбец1]] -> 1006009
A22: 21 | B22: =HLOOKUP($A$1,data!$A$1:$IP$201,A22+1,0) -> 999 | T22: =__Anonymous_Sheet_DB__1[[#This Row],[Столбец1]]*__Anonymous_Sheet_DB__1[[#This Row],[Столбец1]] -> 998001
A23: 22 | B23: =HLOOKUP($A$1,data!$A$1:$IP$201,A23+1,0) -> 1009 | T23: =__Anonymous_Sheet_DB__1[[#This Row],[Столбец1]]*__Anonymous_Sheet_DB__1[[#This Row],[Столбец1]] -> 1018081
A24: 23 | B24: =HLOOKUP($A$1,data!$A$1:$IP$201,A24+1,0) -> 981 | K24: Найти: | L24: 6. Найти асимметрию | N24: -11.989458 | O24: -0.011537984 | T24: =__Anonymous_Sheet_DB__1[[#This Row],[Столбец1]]*__Anonymous_Sheet_DB__1[[#This Row],[Столбец1]] -> 962361
A25: 24 | B25: =HLOOKUP($A$1,data!$A$1:$IP$201,A25+1,0) -> 997 | T25: =__Anonymous_Sheet_DB__1[[#This Row],[Столбец1]]*__Anonymous_Sheet_DB__1[[#This Row],[Столбец1]] -> 994009
A26: 25 | B26: =HLOOKUP($A$1,data!$A$1:$IP$201,A26+1,0) -> 1001 | L26: 7. Найти эксцесс | N26: =SUM(R5:R15)/SUM(H5:H15) -> 31201.618 | O26: =N26/(N2)^4 - 3 -> -0.035503335 | T26: =__Anonymous_Sheet_DB__1[[#This Row],[Столбец1]]*__Anonymous_Sheet_DB__1[[#This Row],[Столбец1]] -> 1002001
A27: 26 | B27: =HLOOKUP($A$1,data!$A$1:$IP$201,A27+1,0) -> 1000 | T27: =__Anonymous_Sheet_DB__1[[#This Row],[Столбец1]]*__Anonymous_Sheet_DB__1[[#This Row],[Столбец1]] -> 1000000
A28: 27 | B28: =HLOOKUP($A$1,data!$A$1:$IP$201,A28+1,0) -> 1008 | L28: 8. оценки Хср и Sв методом квантилей по 4 и 8 интервалам | T28: =__Anonymous_Sheet_DB__1[[#This Row],[Столбец1]]*__Anonymous_Sheet_DB__1[[#This Row],[Столбец1]] -> 1016064
A29: 28 | B29: =HLOOKUP($A$1,data!$A$1:$IP$201,A29+1,0) -> 983 | T29: =__Anonymous_Sheet_DB__1[[#This Row],[Столбец1]]*__Anonymous_Sheet_DB__1[[#This Row],[Столбец1]] -> 966289
A30: 29 | B30: =HLOOKUP($A$1,data!$A$1:$IP$201,A30+1,0) -> 1005 | L30: 9. Значение критерия хи-квадрат по формуле , | T30: =__Anonymous_Sheet_DB__1[[#This Row],[Столбец1]]*__Anonymous_Sheet_DB__1[[#This Row],[Столбец1]] -> 1010025
A31: 30 | B31: =HLOOKUP($A$1,data!$A$1:$IP$201,A31+1,0) -> 991 | L31: где Pi - теоретическая вероятность попадания | T31: =__Anonymous_Sheet_DB__1[[#This Row],[Столбец1]]*__Anonymous_Sheet_DB__1[[#This Row],[Столбец1]] -> 982081
A32: 31 | B32: =HLOOKUP($A$1,data!$A$1:$IP$201,A32+1,0) -> 994 | L32: числа в i-ый интервал (на основе Xср и Sв, найденным прямым | T32: =__Anonymous_Sheet_DB__1[[#This Row],[Столбец1]]*__Anonymous_Sheet_DB__1[[#This Row],[Столбец1]] -> 988036
A33: 32 | B33: =HLOOKUP($A$1,data!$A$1:$IP$201,A33+1,0) -> 998 | L33: вычислением по выборке - НЕ по методу квантилей!) | T33: =__Anonymous_Sheet_DB__1[[#This Row],[Столбец1]]*__Anonymous_Sheet_DB__1[[#This Row],[Столбец1]] -> 996004
A34: 33 | B34: =HLOOKUP($A$1,data!$A$1:$IP$201,A34+1,0) -> 995 | L34: Найти критическое значение хи-квадрат с учетом количества интервалов | T34: =__Anonymous_Sheet_DB__1[[#This Row],[Столбец1]]*__Anonymous_Sheet_DB__1[[#This Row],[Столбец1]] -> 990025
A35: 34 | B35: =HLOOKUP($A$1,data!$A$1:$IP$201,A35+1,0) -> 1008 | L35: Сравнить свое значение критерия хи-квадрат с критическим | T35: =__Anonymous_Sheet_DB__1[[#This Row],[Столбец1]]*__Anonymous_Sheet_DB__1[[#This Row],[Столбец1]] -> 1016064
A36: 35 | B36: =HLOOKUP($A$1,data!$A$1:$IP$201,A36+1,0) -> 996 | T36: =__Anonymous_Sheet_DB__1[[#This Row],[Столбец1]]*__Anonymous_Sheet_DB__1[[#This Row],[Столбец1]] -> 992016
A37: 36 | B37: =HLOOKUP($A$1,data!$A$1:$IP$201,A37+1,0) -> 998 | D37: 10. Найти по первым n = 20 числам доверительный интервал для математического ожидания | T37: =__Anonymous_Sheet_DB__1[[#This Row],[Столбец1]]*__Anonymous_Sheet_DB__1[[#This Row],[Столбец1]] -> 996004
A38: 37 | B38: =HLOOKUP($A$1,data!$A$1:$IP$201,A38+1,0) -> 976 | T38: =__Anonymous_Sheet_DB__1[[#This Row],[Столбец1]]*__Anonymous_Sheet_DB__1[[#This Row],[Столбец1]] -> 952576
A39: 38 | B39: =HLOOKUP($A$1,data!$A$1:$IP$201,A39+1,0) -> 984 | T39: =__Anonymous_Sheet_DB__1[[#This Row],[Столбец1]]*__Anonymous_Sheet_DB__1[[#This Row],[Столбец1]] -> 968256
A40: 39 | B40: =HLOOKUP($A$1,data!$A$1:$IP$201,A40+1,0) -> 979 | T40: =__Anonymous_Sheet_DB__1[[#This Row],[Столбец1]]*__Anonymous_Sheet_DB__1[[#This Row],[Столбец1]] -> 958441
...
